Workbook

Sheet Channel_Efficiency
A1: Channel Efficiency — Baseline Data & Response Rates
A2: Blue cells are inputs (edit with real numbers). Ratios drive all scenario projections below — keep them constant unless channel efficiency itself is expected to change.
A4: Channel | B4: Baseline Budget | C4: Baseline Leads | D4: Baseline Conversions | E4: Baseline Revenue | F4: Leads per $1,000 | G4: Conversion Rate | H4: Revenue per Conversion
A5: Paid Search | B5: 15000 | C5: 620 | D5: 95 | E5: 57000 | F5: =IFERROR(C5/(B5/1000),0) -> 41.333333 | G5: =IFERROR(D5/C5,0) -> 0.15322581 | H5: =IFERROR(E5/D5,0) -> 600
A6: Social Media | B6: 10000 | C6: 540 | D6: 60 | E6: 33000 | F6: =IFERROR(C6/(B6/1000),0) -> 54 | G6: =IFERROR(D6/C6,0) -> 0.11111111 | H6: =IFERROR(E6/D6,0) -> 550
A7: Email | B7: 4000 | C7: 300 | D7: 70 | E7: 56000 | F7: =IFERROR(C7/(B7/1000),0) -> 75 | G7: =IFERROR(D7/C7,0) -> 0.23333333 | H7: =IFERROR(E7/D7,0) -> 800
A8: Content/SEO | B8: 6000 | C8: 260 | D8: 40 | E8: 26000 | F8: =IFERROR(C8/(B8/1000),0) -> 43.333333 | G8: =IFERROR(D8/C8,0) -> 0.15384615 | H8: =IFERROR(E8/D8,0) -> 650
A9: Partnerships | B9: 12000 | C9: 180 | D9: 55 | E9: 71500 | F9: =IFERROR(C9/(B9/1000),0) -> 15 | G9: =IFERROR(D9/C9,0) -> 0.30555556 | H9: =IFERROR(E9/D9,0) -> 1300
A10: Events | B10: 9000 | C10: 150 | D10: 25 | E10: 22500 | F10: =IFERROR(C10/(B10/1000),0) -> 16.666667 | G10: =IFERROR(D10/C10,0) -> 0.16666667 | H10: =IFERROR(E10/D10,0) -> 900

Sheet Scenario_Model
A1: GTM Scenario & What-If Analysis
A2: Each scenario reallocates the channel budgets from Channel_Efficiency; leads/conversions/revenue are projected using that sheet's response rates.
A4: Scenario Assumptions
A5: Social Media spend increase (Scenario 1) | C5: 0.2
A6: Additional events (Scenario 2) | C6: 3
A7: Average cost per event ($) | C7: 3000
A9: Baseline
A10: Channel | B10: Budget | C10: Projected Leads | D10: Projected Conversions | E10: Projected Revenue | F10: CAC | G10: ROI %
A11: Paid Search | B11: =Channel_Efficiency!$B$5 -> 15000 | C11: =B11/1000*Channel_Efficiency!$F$5 -> 620 | D11: =C11*Channel_Efficiency!$G$5 -> 95 | E11: =D11*Channel_Efficiency!$H$5 -> 57000 | F11: =IFERROR(B11/D11,0) -> 157.89474 | G11: =IFERROR((E11-B11)/B11,0) -> 2.8
A12: Social Media | B12: =Channel_Efficiency!$B$6 -> 10000 | C12: =B12/1000*Channel_Efficiency!$F$6 -> 540 | D12: =C12*Channel_Efficiency!$G$6 -> 60 | E12: =D12*Channel_Efficiency!$H$6 -> 33000 | F12: =IFERROR(B12/D12,0) -> 166.66667 | G12: =IFERROR((E12-B12)/B12,0) -> 2.3
A13: Email | B13: =Channel_Efficiency!$B$7 -> 4000 | C13: =B13/1000*Channel_Efficiency!$F$7 -> 300 | D13: =C13*Channel_Efficiency!$G$7 -> 70 | E13: =D13*Channel_Efficiency!$H$7 -> 56000 | F13: =IFERROR(B13/D13,0) -> 57.142857 | G13: =IFERROR((E13-B13)/B13,0) -> 13
A14: Content/SEO | B14: =Channel_Efficiency!$B$8 -> 6000 | C14: =B14/1000*Channel_Efficiency!$F$8 -> 260 | D14: =C14*Channel_Efficiency!$G$8 -> 40 | E14: =D14*Channel_Efficiency!$H$8 -> 26000 | F14: =IFERROR(B14/D14,0) -> 150 | G14: =IFERROR((E14-B14)/B14,0) -> 3.3333333
A15: Partnerships | B15: =Channel_Efficiency!$B$9 -> 12000 | C15: =B15/1000*Channel_Efficiency!$F$9 -> 180 | D15: =C15*Channel_Efficiency!$G$9 -> 55 | E15: =D15*Channel_Efficiency!$H$9 -> 71500 | F15: =IFERROR(B15/D15,0) -> 218.18182 | G15: =IFERROR((E15-B15)/B15,0) -> 4.9583333
A16: Events | B16: =Channel_Efficiency!$B$10 -> 9000 | C16: =B16/1000*Channel_Efficiency!$F$10 -> 150 | D16: =C16*Channel_Efficiency!$G$10 -> 25 | E16: =D16*Channel_Efficiency!$H$10 -> 22500 | F16: =IFERROR(B16/D16,0) -> 360 | G16: =IFERROR((E16-B16)/B16,0) -> 1.5
A17: TOTAL | B17: =SUM(B11:B16) -> 56000 | C17: =SUM(C11:C16) -> 2050 | D17: =SUM(D11:D16) -> 345 | E17: =SUM(E11:E16) -> 266000 | F17: =IFERROR(B17/D17,0) -> 162.31884 | G17: =IFERROR((E17-B17)/B17,0) -> 3.75
A20: Scenario 1 | B20: Heavy Social Media Spend (+20%)
A21: Channel | B21: Budget | C21: Projected Leads | D21: Projected Conversions | E21: Projected Revenue | F21: CAC | G21: ROI %
A22: Paid Search | B22: =Channel_Efficiency!$B$5 -> 15000 | C22: =B22/1000*Channel_Efficiency!$F$5 -> 620 | D22: =C22*Channel_Efficiency!$G$5 -> 95 | E22: =D22*Channel_Efficiency!$H$5 -> 57000 | F22: =IFERROR(B22/D22,0) -> 157.89474 | G22: =IFERROR((E22-B22)/B22,0) -> 2.8
A23: Social Media | B23: =Channel_Efficiency!$B$6*(1+$C$5) -> 12000 | C23: =B23/1000*Channel_Efficiency!$F$6 -> 648 | D23: =C23*Channel_Efficiency!$G$6 -> 72 | E23: =D23*Channel_Efficiency!$H$6 -> 39600 | F23: =IFERROR(B23/D23,0) -> 166.66667 | G23: =IFERROR((E23-B23)/B23,0) -> 2.3
A24: Email | B24: =Channel_Efficiency!$B$7 -> 4000 | C24: =B24/1000*Channel_Efficiency!$F$7 -> 300 | D24: =C24*Channel_Efficiency!$G$7 -> 70 | E24: =D24*Channel_Efficiency!$H$7 -> 56000 | F24: =IFERROR(B24/D24,0) -> 57.142857 | G24: =IFERROR((E24-B24)/B24,0) -> 13
A25: Content/SEO | B25: =Channel_Efficiency!$B$8 -> 6000 | C25: =B25/1000*Channel_Efficiency!$F$8 -> 260 | D25: =C25*Channel_Efficiency!$G$8 -> 40 | E25: =D25*Channel_Efficiency!$H$8 -> 26000 | F25: =IFERROR(B25/D25,0) -> 150 | G25: =IFERROR((E25-B25)/B25,0) -> 3.3333333
A26: Partnerships | B26: =Channel_Efficiency!$B$9 -> 12000 | C26: =B26/1000*Channel_Efficiency!$F$9 -> 180 | D26: =C26*Channel_Efficiency!$G$9 -> 55 | E26: =D26*Channel_Efficiency!$H$9 -> 71500 | F26: =IFERROR(B26/D26,0) -> 218.18182 | G26: =IFERROR((E26-B26)/B26,0) -> 4.9583333
A27: Events | B27: =Channel_Efficiency!$B$10 -> 9000 | C27: =B27/1000*Channel_Efficiency!$F$10 -> 150 | D27: =C27*Channel_Efficiency!$G$10 -> 25 | E27: =D27*Channel_Efficiency!$H$10 -> 22500 | F27: =IFERROR(B27/D27,0) -> 360 | G27: =IFERROR((E27-B27)/B27,0) -> 1.5
A28: TOTAL | B28: =SUM(B22:B27) -> 58000 | C28: =SUM(C22:C27) -> 2158 | D28: =SUM(D22:D27) -> 357 | E28: =SUM(E22:E27) -> 272600 | F28: =IFERROR(B28/D28,0) -> 162.46499 | G28: =IFERROR((E28-B28)/B28,0) -> 3.7
A31: Scenario 2 | B31: Event-Driven Strategy (+3 events)
A32: Channel | B32: Budget | C32: Projected Leads | D32: Projected Conversions | E32: Projected Revenue | F32: CAC | G32: ROI %
A33: Paid Search | B33: =Channel_Efficiency!$B$5 -> 15000 | C33: =B33/1000*Channel_Efficiency!$F$5 -> 620 | D33: =C33*Channel_Efficiency!$G$5 -> 95 | E33: =D33*Channel_Efficiency!$H$5 -> 57000 | F33: =IFERROR(B33/D33,0) -> 157.89474 | G33: =IFERROR((E33-B33)/B33,0) -> 2.8
A34: Social Media | B34: =Channel_Efficiency!$B$6 -> 10000 | C34: =B34/1000*Channel_Efficiency!$F$6 -> 540 | D34: =C34*Channel_Efficiency!$G$6 -> 60 | E34: =D34*Channel_Efficiency!$H$6 -> 33000 | F34: =IFERROR(B34/D34,0) -> 166.66667 | G34: =IFERROR((E34-B34)/B34,0) -> 2.3
A35: Email | B35: =Channel_Efficiency!$B$7 -> 4000 | C35: =B35/1000*Channel_Efficiency!$F$7 -> 300 | D35: =C35*Channel_Efficiency!$G$7 -> 70 | E35: =D35*Channel_Efficiency!$H$7 -> 56000 | F35: =IFERROR(B35/D35,0) -> 57.142857 | G35: =IFERROR((E35-B35)/B35,0) -> 13
A36: Content/SEO | B36: =Channel_Efficiency!$B$8 -> 6000 | C36: =B36/1000*Channel_Efficiency!$F$8 -> 260 | D36: =C36*Channel_Efficiency!$G$8 -> 40 | E36: =D36*Channel_Efficiency!$H$8 -> 26000 | F36: =IFERROR(B36/D36,0) -> 150 | G36: =IFERROR((E36-B36)/B36,0) -> 3.3333333
A37: Partnerships | B37: =Channel_Efficiency!$B$9 -> 12000 | C37: =B37/1000*Channel_Efficiency!$F$9 -> 180 | D37: =C37*Channel_Efficiency!$G$9 -> 55 | E37: =D37*Channel_Efficiency!$H$9 -> 71500 | F37: =IFERROR(B37/D37,0) -> 218.18182 | G37: =IFERROR((E37-B37)/B37,0) -> 4.9583333
A38: Events | B38: =Channel_Efficiency!$B$10+($C$6*$C$7) -> 18000 | C38: =B38/1000*Channel_Efficiency!$F$10 -> 300 | D38: =C38*Channel_Efficiency!$G$10 -> 50 | E38: =D38*Channel_Efficiency!$H$10 -> 45000 | F38: =IFERROR(B38/D38,0) -> 360 | G38: =IFERROR((E38-B38)/B38,0) -> 1.5
A39: TOTAL | B39: =SUM(B33:B38) -> 65000 | C39: =SUM(C33:C38) -> 2200 | D39: =SUM(D33:D38) -> 370 | E39: =SUM(E33:E38) -> 288500 | F39: =IFERROR(B39/D39,0) -> 175.67568 | G39: =IFERROR((E39-B39)/B39,0) -> 3.4384615
A42: Scenario 3 | B42: Balanced Mix (equal split across channels)
A43: Channel | B43: Budget | C43: Projected Leads | D43: Projected Conversions | E43: Projected Revenue | F43: CAC | G43: ROI %
A44: Paid Search | B44: =(SUM(Channel_Efficiency!$B$5:$B$10))/6 -> 9333.3333 | C44: =B44/1000*Channel_Efficiency!$F$5 -> 385.77778 | D44: =C44*Channel_Efficiency!$G$5 -> 59.111111 | E44: =D44*Channel_Efficiency!$H$5 -> 35466.667 | F44: =IFERROR(B44/D44,0) -> 157.89474 | G44: =IFERROR((E44-B44)/B44,0) -> 2.8
A45: Social Media | B45: =(SUM(Channel_Efficiency!$B$5:$B$10))/6 -> 9333.3333 | C45: =B45/1000*Channel_Efficiency!$F$6 -> 504 | D45: =C45*Channel_Efficiency!$G$6 -> 56 | E45: =D45*Channel_Efficiency!$H$6 -> 30800 | F45: =IFERROR(B45/D45,0) -> 166.66667 | G45: =IFERROR((E45-B45)/B45,0) -> 2.3
A46: Email | B46: =(SUM(Channel_Efficiency!$B$5:$B$10))/6 -> 9333.3333 | C46: =B46/1000*Channel_Efficiency!$F$7 -> 700 | D46: =C46*Channel_Efficiency!$G$7 -> 163.33333 | E46: =D46*Channel_Efficiency!$H$7 -> 130666.67 | F46: =IFERROR(B46/D46,0) -> 57.142857 | G46: =IFERROR((E46-B46)/B46,0) -> 13
A47: Content/SEO | B47: =(SUM(Channel_Efficiency!$B$5:$B$10))/6 -> 9333.3333 | C47: =B47/1000*Channel_Efficiency!$F$8 -> 404.44444 | D47: =C47*Channel_Efficiency!$G$8 -> 62.222222 | E47: =D47*Channel_Efficiency!$H$8 -> 40444.444 | F47: =IFERROR(B47/D47,0) -> 150 | G47: =IFERROR((E47-B47)/B47,0) -> 3.3333333
A48: Partnerships | B48: =(SUM(Channel_Efficiency!$B$5:$B$10))/6 -> 9333.3333 | C48: =B48/1000*Channel_Efficiency!$F$9 -> 140 | D48: =C48*Channel_Efficiency!$G$9 -> 42.777778 | E48: =D48*Channel_Efficiency!$H$9 -> 55611.111 | F48: =IFERROR(B48/D48,0) -> 218.18182 | G48: =IFERROR((E48-B48)/B48,0) -> 4.9583333
...

Sheet Scenario_Manager_Guide
A1: Optional: Set Up Native Excel Scenario Manager
A2: This workbook already computes and compares all 3 scenarios side-by-side on the Scenario_Model tab. If you'd also like Excel's built-in toggle (Data > What-If Analysis > Scenario Manager) — which lets you flip between scenarios one at a time on a single live model — follow these steps.
A4: 1. Pick your changing cells | B4: On Channel_Efficiency, the changing cells are the Baseline Budget inputs (B5:B10). These are what each scenario overrides.
A5: 2. Open Scenario Manager | B5: Select the range B5:B10, then go to Data tab > What-If Analysis > Scenario Manager > Add.
A6: 3. Create 'Heavy Social Media' scenario | B6: Name it, keep the same changing cells, and enter budget values with Social Media increased 20% (e.g. 12,000 instead of 10,000) and all other channels unchanged.
A7: 4. Create 'Event-Driven' scenario | B7: Same changing cells; increase only the Events budget by 3 x cost-per-event (e.g. 9,000 + 9,000 = 18,000), leave others unchanged.
A8: 5. Create 'Balanced Mix' scenario | B8: Same changing cells; set every channel's budget to Total Budget / 6 (equal split).
A9: 6. View results | B9: In Scenario Manager, click 'Show' on any scenario to instantly overwrite the budget cells and watch Leads, CAC, and ROI% recalculate live on Scenario_Model.
A10: 7. Generate a summary report (optional) | B10: Click 'Summary' in Scenario Manager, set the result cells to the Total row's Leads, CAC, and ROI% cells on Scenario_Model, and Excel will build its own native scenario summary sheet.
